Workbook

Sheet Saldo Aktif Tahunan
A1: Laporan Keuanggan OSHAN masa khidmat 2024-2025
A2: No | B2: Total Program Per-bulan | C2: Bulan | D2: Nama program | F2: Saldo yang diterima | G2: Saldo yang terpakai | H2: Saldo tambahan | I2: Sisa saldo | K2: Jumlah saldo aktif
I4: =F5-G5+H5 -> 6974000
D5: Total Program | E5: =SUM(B7:B103) -> 50 | F5: =SUM(F7:F103) -> 81023000 | G5: =SUM(G7:G103) -> 74077000 | H5: =SUM(H7:H103) -> 28000 | I5: Plus | J5: Minus
A7: 1 | B7: =COUNTA(D7:E8) -> 2 | C7: Oktober 2024 | D7: Pelantikan OSHAN 24-25 | F7: 7900000 | G7: 7652500 | H7: 0 | I7: =IF(F7>G7,F7-G7,0) -> 247500 | J7: =IF(F7<G7,G7-F7,0)+H7 -> 0 | K7: =IF(OR(F7<>0,G7<>0),SUM($F$7:F7)-SUM($G$7:G7)+SUM($H$7:H7),0) -> 247500
A8: 2 | D8: Rapat Kerja OSHAN 24-25 | F8: 4818000 | G8: 4020500 | H8: 0 | I8: =IF(F8>G8,F8-G8,0) -> 797500 | J8: =IF(F8<G8,G8-F8,0)+H8 -> 0 | K8: =IF(OR(F8<>0,G8<>0),SUM($F$7:F8)-SUM($G$7:G8)+SUM($H$7:H8),0) -> 1045000
A9: 3 | B9: =COUNTA(D9:E17) -> 9 | C9: November 2024 | D9: Penyampulan Al Quran Wakaf | F9: 700000 | G9: 582000 | H9: 0 | I9: =IF(F9>G9,F9-G9,0) -> 118000 | J9: =IF(F9<G9,G9-F9,0)+H9 -> 0 | K9: =IF(OR(F9<>0,G9<>0),SUM($F$7:F9)-SUM($G$7:G9)+SUM($H$7:H9),0) -> 1163000
A10: 4 | D10: Pengadaan Stempel Lughoh | F10: 450000 | G10: 633500 | H10: 0 | I10: =IF(F10>G10,F10-G10,0) -> 0 | J10: =IF(F10<G10,G10-F10,0)+H10 -> 183500 | K10: =IF(OR(F10<>0,G10<>0),SUM($F$7:F10)-SUM($G$7:G10)+SUM($H$7:H10),0) -> 979500
A11: 5 | D11: Pengadaan Inventaris Qism Ta,lim | F11: 500000 | G11: 477000 | H11: 0 | I11: =IF(F11>G11,F11-G11,0) -> 23000 | J11: =IF(F11<G11,G11-F11,0)+H11 -> 0 | K11: =IF(OR(F11<>0,G11<>0),SUM($F$7:F11)-SUM($G$7:G11)+SUM($H$7:H11),0) -> 1002500
A12: 6 | D12: Healty Care Club | F12: 200000 | G12: 199000 | H12: 0 | I12: =IF(F12>G12,F12-G12,0) -> 1000 | J12: =IF(F12<G12,G12-F12,0)+H12 -> 0 | K12: =IF(OR(F12<>0,G12<>0),SUM($F$7:F12)-SUM($G$7:G12)+SUM($H$7:H12),0) -> 1003500
A13: 7 | D13: Seminar Fotografi | F13: 650000 | G13: 657000 | H13: 7000 | I13: =IF(F13>G13,F13-G13,0) -> 0 | J13: =IF(F13<G13,G13-F13,0)+H13 -> 14000 | K13: =IF(OR(F13<>0,G13<>0),SUM($F$7:F13)-SUM($G$7:G13)+SUM($H$7:H13),0) -> 1003500
A14: 8 | D14: Mading Kesehatan & Haen Times | F14: 1440000 | G14: 1123000 | H14: 0 | I14: =IF(F14>G14,F14-G14,0) -> 317000 | J14: =IF(F14<G14,G14-F14,0)+H14 -> 0 | K14: =IF(OR(F14<>0,G14<>0),SUM($F$7:F14)-SUM($G$7:G14)+SUM($H$7:H14),0) -> 1320500
A15: 9 | D15: Jum,at Sehat | F15: 2060000 | G15: 1900000 | H15: 0 | I15: =IF(F15>G15,F15-G15,0) -> 160000 | J15: =IF(F15<G15,G15-F15,0)+H15 -> 0 | K15: =IF(OR(F15<>0,G15<>0),SUM($F$7:F15)-SUM($G$7:G15)+SUM($H$7:H15),0) -> 1480500
A16: 10 | D16: Inventaris Qism Amn | F16: 1780000 | G16: 1780000 | H16: 0 | I16: =IF(F16>G16,F16-G16,0) -> 0 | J16: =IF(F16<G16,G16-F16,0)+H16 -> 0 | K16: =IF(OR(F16<>0,G16<>0),SUM($F$7:F16)-SUM($G$7:G16)+SUM($H$7:H16),0) -> 1480500
A17: 10 | D17: Inventaris Thobiah | F17: 900000 | G17: 564000 | H17: 0 | I17: =IF(F17>G17,F17-G17,0) -> 336000 | J17: =IF(F17<G17,G17-F17,0)+H17 -> 0 | K17: =IF(OR(F17<>0,G17<>0),SUM($F$7:F17)-SUM($G$7:G17)+SUM($H$7:H17),0) -> 1816500
A18: 11 | B18: =COUNTA(D18:E20) -> 3 | C18: Desember 2024 | D18: lomba Kebersihan Asrama | F18: 3750000 | G18: 3398500 | H18: 0 | I18: =IF(F18>G18,F18-G18,0) -> 351500 | J18: =IF(F18<G18,G18-F18,0)+H18 -> 0 | K18: =IF(OR(F18<>0,G18<>0),SUM($F$7:F18)-SUM($G$7:G18)+SUM($H$7:H18),0) -> 2168000
A19: 12 | D19: Inventaris Kantor OSHAN | F19: 2740000 | G19: 2307000 | H19: 0 | I19: =IF(F19>G19,F19-G19,0) -> 433000 | J19: =IF(F19<G19,G19-F19,0)+H19 -> 0 | K19: =IF(OR(F19<>0,G19<>0),SUM($F$7:F19)-SUM($G$7:G19)+SUM($H$7:H19),0) -> 2601000
A20: 13 | D20: Alat-alat Jual beli Qism Ekonomi | F20: 2420000 | G20: 2397000 | H20: 0 | I20: =IF(F20>G20,F20-G20,0) -> 23000 | J20: =IF(F20<G20,G20-F20,0)+H20 -> 0 | K20: =IF(OR(F20<>0,G20<>0),SUM($F$7:F20)-SUM($G$7:G20)+SUM($H$7:H20),0) -> 2624000
A21: 14 | B21: =COUNTA(D21:E29) -> 9 | C21: Januari 2025 | D21: Buku Panduan Qism Lughah | F21: 1950000 | G21: 1866500 | H21: 0 | I21: =IF(F21>G21,F21-G21,0) -> 83500 | J21: =IF(F21<G21,G21-F21,0)+H21 -> 0 | K21: =IF(OR(F21<>0,G21<>0),SUM($F$7:F21)-SUM($G$7:G21)+SUM($H$7:H21),0) -> 2707500
A22: 15 | D22: Hadiah Angkatan Meeting | F22: 4800000 | G22: 3468500 | H22: 0 | I22: =IF(F22>G22,F22-G22,0) -> 1331500 | J22: =IF(F22<G22,G22-F22,0)+H22 -> 0 | K22: =IF(OR(F22<>0,G22<>0),SUM($F$7:F22)-SUM($G$7:G22)+SUM($H$7:H22),0) -> 4039000
A23: 16 | D23: Konsumsi Panitia 3 hari | F23: 450000 | G23: 450000 | H23: 0 | I23: =IF(F23>G23,F23-G23,0) -> 0 | J23: =IF(F23<G23,G23-F23,0)+H23 -> 0 | K23: =IF(OR(F23<>0,G23<>0),SUM($F$7:F23)-SUM($G$7:G23)+SUM($H$7:H23),0) -> 4039000
A24: 17 | D24: TTS Sains Ta'lim | F24: 350000 | G24: 377000 | H24: 0 | I24: =IF(F24>G24,F24-G24,0) -> 0 | J24: =IF(F24<G24,G24-F24,0)+H24 -> 27000 | K24: =IF(OR(F24<>0,G24<>0),SUM($F$7:F24)-SUM($G$7:G24)+SUM($H$7:H24),0) -> 4012000
A25: 18 | D25: Hadiah lomba kaligrafi | F25: 655000 | G25: 468500 | H25: 0 | I25: =IF(F25>G25,F25-G25,0) -> 186500 | J25: =IF(F25<G25,G25-F25,0)+H25 -> 0 | K25: =IF(OR(F25<>0,G25<>0),SUM($F$7:F25)-SUM($G$7:G25)+SUM($H$7:H25),0) -> 4198500
A26: 19 | D26: Hadiah lomba fotografi | F26: 750000 | G26: 740000 | H26: 0 | I26: =IF(F26>G26,F26-G26,0) -> 10000 | J26: =IF(F26<G26,G26-F26,0)+H26 -> 0 | K26: =IF(OR(F26<>0,G26<>0),SUM($F$7:F26)-SUM($G$7:G26)+SUM($H$7:H26),0) -> 4208500
A27: 20 | D27: Banner Kebersihan | F27: 670000 | G27: 470000 | H27: 0 | I27: =IF(F27>G27,F27-G27,0) -> 200000 | J27: =IF(F27<G27,G27-F27,0)+H27 -> 0 | K27: =IF(OR(F27<>0,G27<>0),SUM($F$7:F27)-SUM($G$7:G27)+SUM($H$7:H27),0) -> 4408500 | P27: 23000
A28: 22 | D28: Mading Taman #1 (Kepemimpinan & WW2) | F28: 1200000 | G28: 593500 | H28: 0 | I28: =IF(F28>G28,F28-G28,0) -> 606500 | J28: =IF(F28<G28,G28-F28,0)+H28 -> 0 | K28: =IF(OR(F28<>0,G28<>0),SUM($F$7:F28)-SUM($G$7:G28)+SUM($H$7:H28),0) -> 5015000 | P28: 1331500
A29: 23 | D29: Stand Ekonomi | F29: 750000 | G29: 1450000 | H29: 0 | I29: =IF(F29>G29,F29-G29,0) -> 0 | J29: =IF(F29<G29,G29-F29,0)+H29 -> 700000 | K29: =IF(OR(F29<>0,G29<>0),SUM($F$7:F29)-SUM($G$7:G29)+SUM($H$7:H29),0) -> 4315000 | N29: Minjemmmm | P29: 0
A30: 24 | B30: =COUNTA(D31:E40) -> 10 | C30: Februari 2025 | D30: Pengembalian Dana OSHAN | F30: 0 | G30: 958500 | H30: 0 | I30: =IF(F30>G30,F30-G30,0) -> 0 | J30: =IF(F30<G30,G30-F30,0)+H30 -> 958500 | K30: =IF(OR(F30<>0,G30<>0),SUM($F$7:F30)-SUM($G$7:G30)+SUM($H$7:H30),0) -> 3356500 | N30: -600000
A31: 25 | D31: Lomba mading asrama | F31: 1115000 | G31: 1276000 | H31: 21000 | I31: =IF(F31>G31,F31-G31,0) -> 0 | J31: =IF(F31<G31,G31-F31,0)+H31 -> 182000 | K31: =IF(OR(F31<>0,G31<>0),SUM($F$7:F31)-SUM($G$7:G31)+SUM($H$7:H31),0) -> 3216500 | N31: -1200000 | P31: -27000
A32: 26 | D32: Poster dakwah | F32: 1950000 | G32: 1099000 | H32: 0 | I32: =IF(F32>G32,F32-G32,0) -> 851000 | J32: =IF(F32<G32,G32-F32,0)+H32 -> 0 | K32: =IF(OR(F32<>0,G32<>0),SUM($F$7:F32)-SUM($G$7:G32)+SUM($H$7:H32),0) -> 4067500 | N32: -500000 | P32: 186500
A33: 27 | D33: Tabligh Akbar | F33: 5400000 | G33: 5212500 | H33: 0 | I33: =IF(F33>G33,F33-G33,0) -> 187500 | J33: =IF(F33<G33,G33-F33,0)+H33 -> 0 | K33: =IF(OR(F33<>0,G33<>0),SUM($F$7:F33)-SUM($G$7:G33)+SUM($H$7:H33),0) -> 4255000 | P33: 10000
A34: 28 | D34: Ats-tsaqafatul islamiyyah | F34: 2300000 | G34: 2195500 | H34: 0 | I34: =IF(F34>G34,F34-G34,0) -> 104500 | J34: =IF(F34<G34,G34-F34,0)+H34 -> 0 | K34: =IF(OR(F34<>0,G34<>0),SUM($F$7:F34)-SUM($G$7:G34)+SUM($H$7:H34),0) -> 4359500
A35: 29 | D35: Lomba kebersihan asrama #2 | F35: 2578000 | G35: 2208000 | H35: 0 | I35: =IF(F35>G35,F35-G35,0) -> 370000 | J35: =IF(F35<G35,G35-F35,0)+H35 -> 0 | K35: =IF(OR(F35<>0,G35<>0),SUM($F$7:F35)-SUM($G$7:G35)+SUM($H$7:H35),0) -> 4729500
A36: 30 | D36: Lomba kebersihan kelas #2 | F36: 1122000 | G36: 1162000 | H36: 0 | I36: =IF(F36>G36,F36-G36,0) -> 0 | J36: =IF(F36<G36,G36-F36,0)+H36 -> 40000 | K36: =IF(OR(F36<>0,G36<>0),SUM($F$7:F36)-SUM($G$7:G36)+SUM($H$7:H36),0) -> 4689500
A37: 31 | D37: Mading Taman #2 (Ramadhan) | F37: 0 | G37: 549500 | H37: 0 | I37: =IF(F37>G37,F37-G37,0) -> 0 | J37: =IF(F37<G37,G37-F37,0)+H37 -> 549500 | K37: =IF(OR(F37<>0,G37<>0),SUM($F$7:F37)-SUM($G$7:G37)+SUM($H$7:H37),0) -> 4140000 | N37: Dana Seharusnya
A38: 32 | D38: TTS Bahasa | F38: 780000 | G38: 591700 | H38: 0 | I38: =IF(F38>G38,F38-G38,0) -> 188300 | J38: =IF(F38<G38,G38-F38,0)+H38 -> 0 | K38: =IF(OR(F38<>0,G38<>0),SUM($F$7:F38)-SUM($G$7:G38)+SUM($H$7:H38),0) -> 4328300 | N38: =SUM(J7:J36,J38:J43,N30:N32) -> -160000
A39: 33 | D39: Haen sport competition vol 1 | F39: 6740000 | G39: 6190000 | H39: 0 | I39: =IF(F39>G39,F39-G39,0) -> 550000 | J39: =IF(F39<G39,G39-F39,0)+H39 -> 0 | K39: =IF(OR(F39<>0,G39<>0),SUM($F$7:F39)-SUM($G$7:G39)+SUM($H$7:H39),0) -> 4878300
A40: 34 | D40: Pengadaan lost and found & To be better box | F40: 250000 | G40: 175000 | H40: 0 | I40: =IF(F40>G40,F40-G40,0) -> 75000 | J40: =IF(F40<G40,G40-F40,0)+H40 -> 0 | K40: =IF(OR(F40<>0,G40<>0),SUM($F$7:F40)-SUM($G$7:G40)+SUM($H$7:H40),0) -> 4953300 | N40: s
A41: 35 | B41: =COUNTA(D41:E44) -> 4 | C41: Maret 2025 | D41: Penghargaan Santri 5 S | F41: 740000 | G41: 775000 | H41: 0 | I41: =IF(F41>G41,F41-G41,0) -> 0 | J41: =IF(F41<G41,G41-F41,0)+H41 -> 35000 | K41: =IF(OR(F41<>0,G41<>0),SUM($F$7:F41)-SUM($G$7:G41)+SUM($H$7:H41),0) -> 4918300
A42: 36 | D42: TTS sejarah Qism I'lan | F42: 720000 | G42: 704000 | H42: 0 | I42: =IF(F42>G42,F42-G42,0) -> 16000 | J42: =IF(F42<G42,G42-F42,0)+H42 -> 0 | K42: =IF(OR(F42<>0,G42<>0),SUM($F$7:F42)-SUM($G$7:G42)+SUM($H$7:H42),0) -> 4934300
...

Sheet Draf
A1: Bulan | B1: Nama Program | C1: Saldo yang diterima | D1: Saldo yang terpakai | E1: Sisa saldo
A2: Januari | B2: Hadiah lomba kaligrafi | C2: 655000 | D2: 468500 | E2: =C2-D2 -> 186500
B3: Mading Taman #1 (Kepemimpinan & WW2) | C3: 1200000 | D3: 593500 | E3: =C3-D3 -> 606500
A4: Februari | B4: Lomba mading asrama | C4: 1115000 | D4: 1276000 | E4: =C4-D4 -> -161000
B5: Mading Taman #2 (Ramadhan) | C5: 0 | D5: 549500 | E5: =C5-D5 -> -549500
B6: Pengadaan lost and found & To be better box | C6: 250000 | D6: 175000 | E6: =C6-D6 -> 75000
A7: Maret | B7: TTS sejarah Qism I'lan | C7: 720000 | D7: 704000 | E7: =C7-D7 -> 16000
B8: Lomba mading kelas | C8: 1200000 | D8: 1075000 | E8: =C8-D8 -> 125000
A9: Mei | B9: Mading taman #3 (Idul adha & palestine) | C9: 1170000 | D9: 746000 | E9: =C9-D9 -> 424000

Sheet LK Tahunan
A1: Tanggal | B1: Bulan | C1: Acara & Program | D1: Keterangan | E1: Keluar | F1: Masuk | G1: Saldo
E2: =SUM(E3:E399) -> 56590200 | F2: =SUM(F3:F420) -> 61166000 | G2: =F2-E2 -> 4575800
A3: 45557 | B3: OKTOBER 2024 | C3: Pelantikan Oshan 2024/2025 | D3: Dana Proposal | E3: - | F3: 7000000 | G3: 7000000
A4: 45559 | D4: Kebutuhan Dekorasi | E4: 1678000 | F4: - | G4: =(G3-E4) -> 5322000
A5: 45573 | D5: Amplop 1 Pak | E5: 25000 | F5: - | G5: =(G4-E5) -> 5297000
D6: Kebutuhan Logistik | E6: 1450000 | F6: - | G6: =(G5-E6) -> 3847000
A7: 45574 | D7: Konsumsi Tukang | E7: 45000 | F7: - | G7: =(G6-E7) -> 3802000
D8: Panggung &Sound System | E8: 2800000 | F8: - | G8: =(G7-E8) -> 1002000
D9: Kebutuhan Logistik | E9: 120000 | F9: - | G9: =(G8-E9) -> 882000
A10: 45575 | D10: Banner | E10: 150000 | F10: - | G10: =(G9-E10) -> 732000
D11: Kebutuhan Logistik | E11: 112500 | F11: - | G11: =(G10-E11) -> 619500
D12: Konsumsi Tukang | E12: 35000 | F12: - | G12: =(G11-E12) -> 584500
D13: Dana Proposal | E13: - | F13: 500000 | G13: =(G12+F13) -> 1084500
D14: Buah-buahan | E14: 358000 | F14: - | G14: =(G13-E14) -> 726500
D15: Print & laminating | E15: 7000 | F15: - | G15: =(G14-E15) -> 719500
D16: Konsumsi Tukang Sound System | E16: 150000 | F16: - | G16: =(G15-E16) -> 569500
D17: Dana Proposal | E17: - | F17: 400000 | G17: =(G16+F17) -> 969500
D18: Konsumsi Asatidz | E18: 650000 | F18: - | G18: =(G17-E18) -> 319500
D19: Air Mineral | E19: 72000 | F19: - | G19: =(G18-E19) -> 247500
A20: 45594 | C20: Rapat Kerja Oshan 2024/2025 | D20: Kebutuhan Logistik | E20: 692000 | F20: - | G20: =(G19-E20) -> -444500
D21: Banner | E21: 240000 | F21: - | G21: =(G20-E21) -> -684500
A22: 45595 | D22: Dana Proposal | E22: - | F22: 4818000 | G22: =(G21+'LK Tahunan'!$F22) -> 4133500
D23: Kebutuhan Logistik | E23: 1186000 | F23: - | G23: =(G22-E23) -> 2947500
A24: 45596 | D24: Kebutuhan Logistik | E24: 1197500 | F24: - | G24: =(G23-E24) -> 1750000
A25: 45599 | D25: Konsumsi Pegawai | E25: 55000 | F25: - | G25: =(G24-E25) -> 1695000
A26: 45603 | D26: Konsumsi Panitia | E26: 650000 | G26: =(G25-E26) -> 1045000
A27: 45603 | B27: NOVEMBER 2024 | C27: Inventaris Qis Ta'lim | D27: Stempel | E27: 105000 | F27: - | G27: =(G26-E27) -> 940000
A28: 45611 | D28: Dana Proposal | E28: - | F28: 500000 | G28: =(G27+'LK Tahunan'!$F28) -> 1440000 | J28: =J27+I28 -> 0
A29: 45612 | D29: Kertas Foto | E29: 60000 | F29: - | G29: =(G28-E29) -> 1380000
D30: Cat Besi | E30: 75000 | F30: - | G30: =(G29-E30) -> 1305000
D31: Thinner | E31: 15000 | F31: - | G31: =(G30-E31) -> 1290000
D32: Engsel | E32: 20000 | F32: - | G32: =(G31-E32) -> 1270000
D33: Semprotan | E33: 60000 | F33: - | G33: =(G32-E33) -> 1210000
D34: Kuas ''4 | E34: 15000 | F34: - | G34: =(G33-E34) -> 1195000
D35: Kuas ''2 | E35: 10000 | F35: - | G35: =(G34-E35) -> 1185000
A36: 45615 | D36: Gembok | E36: 117000 | F36: - | G36: =(G35-E36) -> 1068000
A37: 45611 | C37: Penyampulan Al-qur'an | D37: Karton Warna | E37: 190000 | F37: - | G37: =(G36-E37) -> 878000
D38: Dana Proposal | E38: - | F38: 700000 | G38: =(G37+'LK Tahunan'!$F38) -> 1578000
A39: 45612 | D39: Sampul Plastik | E39: 162000 | F39: - | G39: =(G38-E39) -> 1416000
D40: 1Pak Karton | E40: 100000 | F40: - | G40: =(G39-E40) -> 1316000
...

Sheet Peminjaman saldo aktif
A1: No | B1: Nama Program | C1: Jumlah pinjaman | D1: Dana yang terpakai | E1: Sisa dana | F1: Status | H1: Kriteria Status
A2: 1 | B2: Inventaris Riyadhoh | C2: 500000 | D2: 500000 | E2: =C2-D2 -> 0 | F2: Lunas | H2: Lunas
A3: 2 | B3: Shoum lovers | C3: 1200000 | D3: 1033500 | E3: =C3-D3 -> 166500 | F3: Lunas | H3: Ngutang
A4: 3 | B4: Mading taman #2 | C4: 600000 | D4: 549500 | E4: =C4-D4 -> 50500
A5: 4 | B5: Jelajah alam | C5: 60000 | D5: 60000 | E5: =C5-D5 -> 0 | F5: Lunas
A6: 5 | B6: Rapat sosialisai funfest 4.0 | C6: 500000 | D6: 436000 | E6: =C6-D6 -> 64000 | F6: Ngutang
A7: 6 | B7: Seminar angkatan | C7: 1050000 | D7: 916500 | E7: =C7-D7 -> 133500 | F7: Lunas
A8: 7 | B8: Lomba kebersihan #3 | C8: 105000 | D8: 105000 | E8: =C8-D8 -> 0 | F8: Lunas
A9: 8 | E9: =C9-D9 -> 0
A10: 9 | E10: =C10-D10 -> 0
A11: 10 | E11: =C11-D11 -> 0
A12: 11 | E12: =C12-D12 -> 0
A13: 12 | E13: =C13-D13 -> 0
A14: 13 | E14: =C14-D14 -> 0
A15: 14 | E15: =C15-D15 -> 0

Sheet Rekapitulasi LK Program perQism
A1: Qism/Divisi | B1: Total Program PerQism | C1: Bulan | D1: Nama Program | E1: Saldo yang diterima | F1: Saldo yang terpakai | G1: Sisa Saldo | K1: Bulan | L1: Nama program | M1: Saldo yang diterima | N1: Saldo yang terpakai
G2: Plus | H2: Minus
A3: Ta'lim Ibadah | B3: =COUNTA(D3:D11) -> 9 | C3: November 2024 | D3: Penyampulan Al Quran Wakaf | E3: 700000 | F3: 582000 | G3: =IF(E3>F3,E3-F3,0) -> 118000 | H3: =IF(F3>E3,F3-E3,0) -> 0 | L3: Total Program | M3: =SUM(M4:M101) -> 0 | N3: =SUM(N4:N101) -> 3108500
D4: Pengadaan Inventaris Qism Ta,lim | E4: 500000 | F4: 477000 | G4: =IF(E4>F4,E4-F4,0) -> 23000 | H4: =IF(F4>E4,F4-E4,0) -> 0
C5: Januari 2025 | D5: TTS Sains Ta'lim | E5: 350000 | F5: 377000 | G5: =IF(E5>F5,E5-F5,0) -> 0 | H5: =IF(F5>E5,F5-E5,0) -> 27000
C6: Februari 2025 | D6: Poster dakwah | E6: 1950000 | F6: 1099000 | G6: =IF(E6>F6,E6-F6,0) -> 851000 | H6: =IF(F6>E6,F6-E6,0) -> 0 | K6: November 2024
D7: Tabligh Akbar | E7: 5400000 | F7: 5212500 | G7: =IF(E7>F7,E7-F7,0) -> 187500 | H7: =IF(F7>E7,F7-E7,0) -> 0
D8: Ats-tsaqafatul islamiyyah | E8: 2300000 | F8: 2195500 | G8: =IF(E8>F8,E8-F8,0) -> 104500 | H8: =IF(F8>E8,F8-E8,0) -> 0
C9: Maret 2025 | D9: Shoum lovers | E9: 1100000 | F9: 1033500 | G9: =IF(E9>F9,E9-F9,0) -> 66500 | H9: =IF(F9>E9,F9-E9,0) -> 0
C10: Mei 2025 | D10: TTS Sejarah Qism ta'lim | E10: 730000 | F10: 530000 | G10: =IF(E10>F10,E10-F10,0) -> 200000 | H10: =IF(F10>E10,F10-E10,0) -> 0
D11: Seminar Angkatan | E11: 1050000 | F11: 916500 | G11: =IF(E11>F11,E11-F11,0) -> 133500 | H11: =IF(F11>E11,F11-E11,0) -> 0
A12: Amn | B12: =COUNTA(D12:D13) -> 2 | C12: November 2024 | D12: Inventaris Qism Amn | E12: 1780000 | F12: 1780000 | G12: =IF(E12>F12,E12-F12,0) -> 0 | H12: =IF(F12>E12,F12-E12,0) -> 0
C13: April 2025 | D13: Jelajah alam | E13: 1775000 | F13: 1575700 | G13: =IF(E13>F13,E13-F13,0) -> 199300 | H13: =IF(F13>E13,F13-E13,0) -> 0
A14: Lughoh | B14: =COUNTA(D14:D17) -> 4 | C14: November 2024 | D14: Pengadaan Stempel Lughoh | E14: 450000 | F14: 633500 | G14: =IF(E14>F14,E14-F14,0) -> 0 | H14: =IF(F14>E14,F14-E14,0) -> 183500
C15: Januari 2025 | D15: Buku Panduan Qism Lughah | E15: 1950000 | F15: 1866500 | G15: =IF(E15>F15,E15-F15,0) -> 83500 | H15: =IF(F15>E15,F15-E15,0) -> 0 | K15: Desember 2024
C16: Februari 2025 | D16: TTS Bahasa | E16: 780000 | F16: 591700 | G16: =IF(E16>F16,E16-F16,0) -> 188300 | H16: =IF(F16>E16,F16-E16,0) -> 0
C17: April 2025 | D17: Buletin OSHAN | E17: 550000 | G17: =IF(E17>F17,E17-F17,0) -> 550000 | H17: =IF(F17>E17,F17-E17,0) -> 0
A18: I'lan | B18: =COUNTA(D18:D27) -> 10 | C18: November 2025 | D18: Mading Kesehatan & Haen Times | E18: 1440000 | F18: 1123000 | G18: =IF(E18>F18,E18-F18,0) -> 317000 | H18: =IF(F18>E18,F18-E18,0) -> 0 | K18: Januari 2025
C19: Januari 2025 | D19: Hadiah lomba kaligrafi | E19: 655000 | F19: 468500 | G19: =IF(E19>F19,E19-F19,0) -> 186500 | H19: =IF(F19>E19,F19-E19,0) -> 0
D20: Mading Taman #1 (Kepemimpinan & WW2) | E20: 1200000 | F20: 593500 | G20: =IF(E20>F20,E20-F20,0) -> 606500 | H20: =IF(F20>E20,F20-E20,0) -> 0
C21: Februari 2025 | D21: Lomba mading asrama | E21: 1115000 | F21: 1276000 | G21: =IF(E21>F21,E21-F21,0) -> 0 | H21: =IF(F21>E21,F21-E21,0) -> 161000
D22: Mading Taman #2 (Ramadhan) | E22: 0 | F22: 549500 | G22: =IF(E22>F22,E22-F22,0) -> 0 | H22: =IF(F22>E22,F22-E22,0) -> 549500
D23: Pengadaan lost and found & To be better box | E23: 250000 | F23: 175000 | G23: =IF(E23>F23,E23-F23,0) -> 75000 | H23: =IF(F23>E23,F23-E23,0) -> 0
C24: Maret 2025 | D24: TTS sejarah Qism I'lan | E24: 720000 | F24: 704000 | G24: =IF(E24>F24,E24-F24,0) -> 16000 | H24: =IF(F24>E24,F24-E24,0) -> 0
D25: Lomba mading kelas | E25: 1200000 | F25: 1075000 | G25: =IF(E25>F25,E25-F25,0) -> 125000 | H25: =IF(F25>E25,F25-E25,0) -> 0
C26: Mei 2025 | D26: Mading taman #3 (Idul adha & palestine) | E26: 1170000 | F26: 746000 | G26: =IF(E26>F26,E26-F26,0) -> 424000 | H26: =IF(F26>E26,F26-E26,0) -> 0
D27: Pembuatan Mading Informasi | E27: 3600000 | G27: =IF(E27>F27,E27-F27,0) -> 3600000 | H27: =IF(F27>E27,F27-E27,0) -> 0 | K27: Februari 2025 | L27: Pengembalian Dana OSHAN | M27: 0 | N27: 958500
A28: Riyadhoh | B28: =COUNTA(D28:D31) -> 4 | C28: Januari 2025 | D28: Hadiah Angkatan Meeting | E28: 4800000 | F28: 3468500 | G28: =IF(E28>F28,E28-F28,0) -> 1331500 | H28: =IF(F28>E28,F28-E28,0) -> 0
D29: Konsumsi Panitia 3 hari | E29: 450000 | F29: 450000 | G29: =IF(E29>F29,E29-F29,0) -> 0 | H29: =IF(F29>E29,F29-E29,0) -> 0
C30: Februari 2025 | D30: Haen sport competition vol 1 | E30: 6740000 | F30: 6190000 | G30: =IF(E30>F30,E30-F30,0) -> 550000 | H30: =IF(F30>E30,F30-E30,0) -> 0
C31: April 2025 | D31: Transportasi Inventaris Riyadhoh | E31: 0 | F31: 200000 | G31: =IF(E31>F31,E31-F31,0) -> 0 | H31: =IF(F31>E31,F31-E31,0) -> 200000
A32: Thobi'ah | B32: =COUNTA(D32:D38) -> 7 | C32: November 2024 | D32: Inventaris Thobiah | E32: 900000 | F32: 564000 | G32: =IF(E32>F32,E32-F32,0) -> 336000 | H32: =IF(F32>E32,F32-E32,0) -> 0
C33: Desember 2024 | D33: lomba Kebersihan Asrama | E33: 3750000 | F33: 3398500 | G33: =IF(E33>F33,E33-F33,0) -> 351500 | H33: =IF(F33>E33,F33-E33,0) -> 0
C34: Januari 2025 | D34: Banner Kebersihan | E34: 670000 | F34: 470000 | G34: =IF(E34>F34,E34-F34,0) -> 200000 | H34: =IF(F34>E34,F34-E34,0) -> 0
C35: Februari 2025 | D35: Lomba kebersihan asrama #2 | E35: 2578000 | F35: 2208000 | G35: =IF(E35>F35,E35-F35,0) -> 370000 | H35: =IF(F35>E35,F35-E35,0) -> 0
D36: Lomba kebersihan kelas #2 | E36: 1122000 | F36: 1162000 | G36: =IF(E36>F36,E36-F36,0) -> 0 | H36: =IF(F36>E36,F36-E36,0) -> 40000
C37: Mei 2025 | D37: Lomba kebersihan Asrama #3 | E37: 2322000 | F37: 2338000 | G37: =IF(E37>F37,E37-F37,0) -> 0 | H37: =IF(F37>E37,F37-E37,0) -> 16000
D38: Lomba kebersihan kelas #3 | E38: 1378000 | F38: 1441600 | G38: =IF(E38>F38,E38-F38,0) -> 0 | H38: =IF(F38>E38,F38-E38,0) -> 63600 | K38: Maret 2025
A39: Shahafi | B39: =COUNTA(D39:D41) -> 3 | C39: November 2024 | D39: Seminar Fotografi | E39: 650000 | F39: 657000 | G39: =IF(E39>F39,E39-F39,0) -> 0 | H39: =IF(F39>E39,F39-E39,0) -> 7000
C40: Januari 2025 | D40: Hadiah lomba fotografi | E40: 750000 | F40: 740000 | G40: =IF(E40>F40,E40-F40,0) -> 10000 | H40: =IF(F40>E40,F40-E40,0) -> 0
...

Sheet kenangan bego-begonya
A1: Tanggal | B1: Keterangan | C1: Keluar | D1: Masuk | E1: Saldo
A2: 45658 | B2: Saldo Aktif Bulan Okt-Des | C2: - | D2: 2784500 | E2: =Table32[[#This Row],[Masuk]] -> 2784500
B3: P.Alat jual beli Qism Ekonomi | C3: - | D3: 23000 | E3: =E2+Table32[[#This Row],[Masuk]] -> 2807500
A4: 45674 | B4: P.Buku Panduan Lugoh | C4: - | D4: 83500 | E4: =E3+Table32[[#This Row],[Masuk]] -> 2891000
B5: P.Hadiah Angkatan Meeting | C5: - | D5: 1331500 | E5: =E4+Table32[[#This Row],[Masuk]] -> 4222500
B6: Latihan Keluar mahad | C6: 110000 | E6: =E5-Table32[[#This Row],[Keluar]] -> 4112500
A7: 45677 | B7: Haen Sport competition | C7: 1021000 | D7: - | E7: =E6-Table32[[#This Row],[Keluar]] -> 3091500
B8: Teka-teki silang ta'lim | C8: 350000 | D8: - | E8: =E7-Table32[[#This Row],[Keluar]] -> 2741500
B9: Hadiah lomba kaligrafi | C9: 655000 | D9: - | E9: =E8-Table32[[#This Row],[Keluar]] -> 2086500
B10: Hadiah lomba fotografi | C10: 750000 | D10: - | E10: =E9-Table32[[#This Row],[Keluar]] -> 1336500
A11: 45680 | B11: Teka-teki silang ta'lim | C11: - | D11: 350000 | E11: =E10+Table32[[#This Row],[Masuk]] -> 1686500
B12: Hadiah lomba kaligrafi | C12: - | D12: 655000 | E12: =E11+Table32[[#This Row],[Masuk]] -> 2341500
B13: Hadiah lomba fotografi | C13: - | D13: 750000 | E13: =E12+Table32[[#This Row],[Masuk]] -> 3091500
A14: 45681 | B14: Konsumsi Panitia HSC | C14: 155000 | D14: - | E14: =E13-Table32[[#This Row],[Keluar]] -> 2936500
B15: TTS Sains (tambahan) | C15: 27000 | D15: - | E15: =E14-Table32[[#This Row],[Keluar]] -> 2909500
A16: 45685 | B16: Stand ekonomi (tambahan) | C16: 700000 | D16: - | E16: =E15-Table32[[#This Row],[Keluar]] -> 2209500
A17: 45687 | B17: Mading Taman | C17: 800000 | D17: - | E17: =E16-Table32[[#This Row],[Keluar]] -> 1409500
A18: 45690 | B18: P.Hadiah Lomba Fotografi | C18: - | D18: 10000 | E18: =E17+Table32[[#This Row],[Masuk]] -> 1419500
B19: P.Hadiah Lomba Kaligrafi | C19: - | D19: 186500 | E19: =E18+Table32[[#This Row],[Masuk]] -> 1606000
A20: 45692 | B20: Mading Taman | C20: - | D20: 800000 | E20: =E19+Table32[[#This Row],[Masuk]] -> 2406000
B21: P. | C21: -
C22: -
C23: -
C24: -
C25: -
